WARNING:__main__:
*****************************************
Setting OMP_NUM_THREADS environment variable for each process to be 1 in default, to avoid your system being overloaded, please further tune the variable for optimal performance in your application as needed. 
*****************************************
/u/ssoma1/.conda/envs/torchprune/bin/python: can't open file '/u/ssoma1/mahdi/Torch-Pruning/finetune_pruned_resnet.py': [Errno 2] No such file or directory
/u/ssoma1/.conda/envs/torchprune/bin/python: can't open file '/u/ssoma1/mahdi/Torch-Pruning/finetune_pruned_resnet.py': [Errno 2] No such file or directory
/u/ssoma1/.conda/envs/torchprune/bin/python: can't open file '/u/ssoma1/mahdi/Torch-Pruning/finetune_pruned_resnet.py': [Errno 2] No such file or directory
/u/ssoma1/.conda/envs/torchprune/bin/python: can't open file '/u/ssoma1/mahdi/Torch-Pruning/finetune_pruned_resnet.py': [Errno 2] No such file or directory
E0718 20:40:10.026000 430803 site-packages/torch/distributed/elastic/multiprocessing/api.py:869] failed (exitcode: 2) local_rank: 0 (pid: 430869) of binary: /u/ssoma1/.conda/envs/torchprune/bin/python
Traceback (most recent call last):
  File "/u/ssoma1/.conda/envs/torchprune/lib/python3.10/runpy.py", line 196, in _run_module_as_main
    return _run_code(code, main_globals, None,
  File "/u/ssoma1/.conda/envs/torchprune/lib/python3.10/runpy.py", line 86, in _run_code
    exec(code, run_globals)
  File "/u/ssoma1/.conda/envs/torchprune/lib/python3.10/site-packages/torch/distributed/run.py", line 923, in <module>
    main()
  File "/u/ssoma1/.conda/envs/torchprune/lib/python3.10/site-packages/torch/distributed/elastic/multiprocessing/errors/__init__.py", line 355, in wrapper
    return f(*args, **kwargs)
  File "/u/ssoma1/.conda/envs/torchprune/lib/python3.10/site-packages/torch/distributed/run.py", line 919, in main
    run(args)
  File "/u/ssoma1/.conda/envs/torchprune/lib/python3.10/site-packages/torch/distributed/run.py", line 910, in run
    elastic_launch(
  File "/u/ssoma1/.conda/envs/torchprune/lib/python3.10/site-packages/torch/distributed/launcher/api.py", line 138, in __call__
    return launch_agent(self._config, self._entrypoint, list(args))
  File "/u/ssoma1/.conda/envs/torchprune/lib/python3.10/site-packages/torch/distributed/launcher/api.py", line 269, in launch_agent
    raise ChildFailedError(
torch.distributed.elastic.multiprocessing.errors.ChildFailedError: 
============================================================
finetune_pruned_resnet.py FAILED
------------------------------------------------------------
Failures:
[1]:
  time      : 2025-07-18_20:40:10
  host      : gpua059.delta.ncsa.illinois.edu
  rank      : 1 (local_rank: 1)
  exitcode  : 2 (pid: 430870)
  error_file: <N/A>
  traceback : To enable traceback see: https://pytorch.org/docs/stable/elastic/errors.html
[2]:
  time      : 2025-07-18_20:40:10
  host      : gpua059.delta.ncsa.illinois.edu
  rank      : 2 (local_rank: 2)
  exitcode  : 2 (pid: 430871)
  error_file: <N/A>
  traceback : To enable traceback see: https://pytorch.org/docs/stable/elastic/errors.html
[3]:
  time      : 2025-07-18_20:40:10
  host      : gpua059.delta.ncsa.illinois.edu
  rank      : 3 (local_rank: 3)
  exitcode  : 2 (pid: 430872)
  error_file: <N/A>
  traceback : To enable traceback see: https://pytorch.org/docs/stable/elastic/errors.html
------------------------------------------------------------
Root Cause (first observed failure):
[0]:
  time      : 2025-07-18_20:40:10
  host      : gpua059.delta.ncsa.illinois.edu
  rank      : 0 (local_rank: 0)
  exitcode  : 2 (pid: 430869)
  error_file: <N/A>
  traceback : To enable traceback see: https://pytorch.org/docs/stable/elastic/errors.html
============================================================
